Workbook

Sheet Overview
A1: Simulated RFP Evaluation: Off-Road Haul Truck Tires
A2: SIMULATED EXERCISE: all suppliers, prices, and performance data are fictitious and created for portfolio demonstration only.
A4: Purpose | B4: Portfolio exercise showing a competitive sourcing evaluation from criteria to award recommendation: weighted scoring plus a 5-year total-cost-of-ownership (TCO) comparison.
A5: Scenario | B5: A fictional aggregates producer is sourcing off-road haul truck tires (radial 29.5R25 class) for a 40-truck fleet under a 5-year supply agreement. Three fictitious suppliers bid.
A6: Disclaimer | B6: SIMULATED. Company names are invented; any resemblance to real companies is coincidental. All bid values and performance claims are made-up assumptions, not market data, and are not connected to any real employer or buyer.
A7: Method | B7: 1) Define weighted criteria. 2) Collect bids on a standard pricing template. 3) Model 5-year TCO (purchase, freight, support, downtime, warranty credits, working-capital benefit), discounted to NPV. 4) Score each supplier 1 to 5 per criterion. 5) Apply weights, rank, and test sensitivity to the weights.
A8: Sheet guide | B8: Assumptions | Criteria | Pricing_Template | Bids | TCO | TCO_Summary | Scoring | Sensitivity | Recommendation
A9: Legend | B9: Blue text = hardcoded input. Black = formula. Green = link from another sheet. Yellow fill = key assumption to review. Change blue cells and every result recalculates.
A10: Key limits | B10: Premature failure rates, tire life, and delivery performance are treated as supplier-reported and unverified. A real evaluation would verify them with references, site trials, and warranty-claim history. Tires purchased per year are modeled as a steady average (fractional) for simplicity.

Sheet Assumptions
A1: Assumptions
A2: SIMULATED EXERCISE: all suppliers, prices, and performance data are fictitious and created for portfolio demonstration only.
A3: Assumption | B3: Value | C3: Basis
A4: Trucks in fleet | B4: 40 | C4: Invented
A5: Tires per truck | B5: 6 | C5: Standard 6-tire haul truck layout
A6: Operating hours per truck per year | B6: 3000 | C6: Invented
A7: Annual tire-hours (fleet) | B7: =B4*B5*B6 -> 720000 | C7: Calculated: trucks x tires x hours
A8: Downtime hours per premature tire failure | B8: 6 | C8: Invented
A9: Downtime cost per hour ($) | B9: 450 | C9: Invented: lost production and standby labour
A10: Cost of capital / discount rate | B10: 0.07 | C10: Invented; used for NPV and working-capital benefit
A11: Contract term (years) | B11: 5 | C11: Model is built for 5 annual columns

Sheet Criteria
A1: Evaluation Criteria and Weights
A2: SIMULATED EXERCISE: all suppliers, prices, and performance data are fictitious and created for portfolio demonstration only.
A4: Criterion | B4: Weight | C4: What is assessed | D4: How scored
A5: Total cost of ownership | B5: 0.4 | C5: 5-year NPV cost: purchase, freight, support, downtime, warranty credits, working capital | D5: Formula: 5 x lowest NPV / supplier NPV
A6: Technical performance & quality | B6: 0.2 | C6: Guaranteed tire life, premature failure rate, spec compliance | D6: Evaluator score 1 to 5
A7: Delivery & service | B7: 0.15 | C7: Lead time, on-time delivery, onsite support | D7: Evaluator score 1 to 5
A8: Supplier risk & compliance | B8: 0.1 | C8: Financial stability, supply continuity, insurance, safety compliance | D8: Evaluator score 1 to 5
A9: Commercial terms | B9: 0.1 | C9: Payment terms, warranty terms, price escalation protection, flexibility | D9: Evaluator score 1 to 5
A10: Sustainability & safety practices | B10: 0.05 | C10: Tire recycling or retread programs, safety record, ESG policy | D10: Evaluator score 1 to 5
A11: Total weight (must equal 100%) | B11: =SUM(B5:B10) -> 1 | C11: =IF(ROUND(B11,6)=1,"OK","CHECK: weights must sum to 100%") -> OK
A14: Score | B14: Meaning
A15: 5 | B15: Excellent: clearly exceeds requirements
A16: 4 | B16: Good: meets requirements with minor strengths
A17: 3 | B17: Acceptable: meets minimum requirements
A18: 2 | B18: Weak: gaps or notable concerns
A19: 1 | B19: Poor: fails requirements or unacceptable risk

Sheet Pricing_Template
A1: Supplier Pricing Template (issued to bidders)
A2: SIMULATED EXERCISE: all suppliers, prices, and performance data are fictitious and created for portfolio demonstration only.
A3: Instructions: complete one row per item. Prices in CAD, delivered to the buyer's yard, excluding GST. Bids must hold for 90 days. Blue row is an EXAMPLE of the expected format.
A5: Line | B5: Item description | C5: Unit | D5: Est. annual qty | E5: Unit price ($) | F5: Freight ($/unit) | G5: Annual escalation (%) | H5: Payment terms (days) | I5: Guaranteed life (hours) | J5: Warranty credit on early failure (%) | K5: Lead time (weeks) | L5: Notes
A6: 1 | B6: EXAMPLE: Radial 29.5R25 rock-service haul truck tire | C6: Each | D6: 150 | E6: 4300 | F6: 90 | G6: 0.03 | H6: 30 | I6: 4400 | J6: 0.5 | K6: 4 | L6: Example only
A7: 2
A8: 3
A10: Supplier declarations (bidder to confirm):
A11: [ ] | B11: Valid commercial liability insurance certificate attached
A12: [ ] | B12: Safety program and incident record attached
A13: [ ] | B13: Three customer references with fleet size and tire life data attached
A14: [ ] | B14: Warranty claim process and response time described
A15: [ ] | B15: All exceptions to the draft agreement listed

Sheet Bids
A1: Bid Data Received (invented)
A2: SIMULATED EXERCISE: all suppliers, prices, and performance data are fictitious and created for portfolio demonstration only.
A4: Bid parameter | B4: Unit | C4: Northfield Tire | D4: Summit Tread | E4: Prairie Rubber
A5: Unit price per tire | B5: $ | C5: 4200 | D5: 4650 | E5: 3700
A6: Guaranteed tire life | B6: hours | C6: 4500 | D6: 5200 | E6: 3800
A7: Freight per tire | B7: $ | C7: 85 | D7: 120 | E7: 60
A8: Annual onsite support fee | B8: $/yr | C8: 12000 | D8: 8000 | E8: 0
A9: Annual price escalation | B9: % | C9: 0.03 | D9: 0.02 | E9: 0.045
A10: Premature failure rate (supplier-reported) | B10: % of tires | C10: 0.04 | D10: 0.02 | E10: 0.08
A11: Warranty credit on premature failures | B11: % of price | C11: 0.5 | D11: 0.75 | E11: 0.25
A12: Payment terms | B12: days | C12: 45 | D12: 30 | E12: 60
A13: Lead time | B13: weeks | C13: 4 | D13: 6 | E13: 3
A14: On-time delivery, last 12 months (supplier-reported) | B14: % | C14: 0.95 | D14: 0.92 | E14: 0.96
A16: All values are invented for this simulation. Lead time and on-time delivery inform the Delivery & service score only; they do not enter the TCO model.

Sheet TCO
A1: 5-Year Total Cost of Ownership by Supplier
A2: SIMULATED EXERCISE: all suppliers, prices, and performance data are fictitious and created for portfolio demonstration only.
A4: =Bids!C4 -> Northfield Tire
A5: Cost line | B5: 1 | C5: 2 | D5: 3 | E5: 4 | F5: 5 | G5: 5-Year total
A6: Tires purchased (avg per year) | B6: =Assumptions!$B$7/Bids!$C$6 -> 160 | C6: =Assumptions!$B$7/Bids!$C$6 -> 160 | D6: =Assumptions!$B$7/Bids!$C$6 -> 160 | E6: =Assumptions!$B$7/Bids!$C$6 -> 160 | F6: =Assumptions!$B$7/Bids!$C$6 -> 160 | G6: =SUM(B6:F6) -> 800
A7: Unit price ($) | B7: =Bids!$C$5*(1+Bids!$C$9)^(B$5-1) -> 4200 | C7: =Bids!$C$5*(1+Bids!$C$9)^(C$5-1) -> 4326 | D7: =Bids!$C$5*(1+Bids!$C$9)^(D$5-1) -> 4455.78 | E7: =Bids!$C$5*(1+Bids!$C$9)^(E$5-1) -> 4589.4534 | F7: =Bids!$C$5*(1+Bids!$C$9)^(F$5-1) -> 4727.137
A8: Purchase cost | B8: =B6*B7 -> 672000 | C8: =C6*C7 -> 692160 | D8: =D6*D7 -> 712924.8 | E8: =E6*E7 -> 734312.54 | F8: =F6*F7 -> 756341.92 | G8: =SUM(B8:F8) -> 3567739.3
A9: Freight | B9: =B6*Bids!$C$7 -> 13600 | C9: =C6*Bids!$C$7 -> 13600 | D9: =D6*Bids!$C$7 -> 13600 | E9: =E6*Bids!$C$7 -> 13600 | F9: =F6*Bids!$C$7 -> 13600 | G9: =SUM(B9:F9) -> 68000
A10: Onsite support fee | B10: =Bids!$C$8 -> 12000 | C10: =Bids!$C$8 -> 12000 | D10: =Bids!$C$8 -> 12000 | E10: =Bids!$C$8 -> 12000 | F10: =Bids!$C$8 -> 12000 | G10: =SUM(B10:F10) -> 60000
A11: Premature failures (tires) | B11: =B6*Bids!$C$10 -> 6.4 | C11: =C6*Bids!$C$10 -> 6.4 | D11: =D6*Bids!$C$10 -> 6.4 | E11: =E6*Bids!$C$10 -> 6.4 | F11: =F6*Bids!$C$10 -> 6.4 | G11: =SUM(B11:F11) -> 32
A12: Downtime cost | B12: =B11*Assumptions!$B$8*Assumptions!$B$9 -> 17280 | C12: =C11*Assumptions!$B$8*Assumptions!$B$9 -> 17280 | D12: =D11*Assumptions!$B$8*Assumptions!$B$9 -> 17280 | E12: =E11*Assumptions!$B$8*Assumptions!$B$9 -> 17280 | F12: =F11*Assumptions!$B$8*Assumptions!$B$9 -> 17280 | G12: =SUM(B12:F12) -> 86400
A13: Warranty credit | B13: =-B11*B7*Bids!$C$11 -> -13440 | C13: =-C11*C7*Bids!$C$11 -> -13843.2 | D13: =-D11*D7*Bids!$C$11 -> -14258.496 | E13: =-E11*E7*Bids!$C$11 -> -14686.251 | F13: =-F11*F7*Bids!$C$11 -> -15126.838 | G13: =SUM(B13:F13) -> -71354.785
A14: Working-capital benefit (payment terms) | B14: =-B8*Assumptions!$B$10*Bids!$C$12/365 -> -5799.4521 | C14: =-C8*Assumptions!$B$10*Bids!$C$12/365 -> -5973.4356 | D14: =-D8*Assumptions!$B$10*Bids!$C$12/365 -> -6152.6387 | E14: =-E8*Assumptions!$B$10*Bids!$C$12/365 -> -6337.2178 | F14: =-F8*Assumptions!$B$10*Bids!$C$12/365 -> -6527.3344 | G14: =SUM(B14:F14) -> -30790.079
A15: Total annual cost | B15: =B8+B9+B10+B12+B13+B14 -> 695640.55 | C15: =C8+C9+C10+C12+C13+C14 -> 715223.36 | D15: =D8+D9+D10+D12+D13+D14 -> 735393.67 | E15: =E8+E9+E10+E12+E13+E14 -> 756169.08 | F15: =F8+F9+F10+F12+F13+F14 -> 777567.75 | G15: =SUM(B15:F15) -> 3679994.4
A16: Discount factor | B16: =1/(1+Assumptions!$B$10)^B$5 -> 0.93457944 | C16: =1/(1+Assumptions!$B$10)^C$5 -> 0.87343873 | D16: =1/(1+Assumptions!$B$10)^D$5 -> 0.81629788 | E16: =1/(1+Assumptions!$B$10)^E$5 -> 0.76289521 | F16: =1/(1+Assumptions!$B$10)^F$5 -> 0.71298618
A17: Present value | B17: =B15*B16 -> 650131.35 | C17: =C15*C16 -> 624703.79 | D17: =D15*D16 -> 600300.29 | E17: =E15*E16 -> 576877.77 | F17: =F15*F16 -> 554395.06 | G17: =SUM(B17:F17) -> 3006408.3
A20: =Bids!D4 -> Summit Tread
A21: Cost line | B21: 1 | C21: 2 | D21: 3 | E21: 4 | F21: 5 | G21: 5-Year total
A22: Tires purchased (avg per year) | B22: =Assumptions!$B$7/Bids!$D$6 -> 138.46154 | C22: =Assumptions!$B$7/Bids!$D$6 -> 138.46154 | D22: =Assumptions!$B$7/Bids!$D$6 -> 138.46154 | E22: =Assumptions!$B$7/Bids!$D$6 -> 138.46154 | F22: =Assumptions!$B$7/Bids!$D$6 -> 138.46154 | G22: =SUM(B22:F22) -> 692.30769
A23: Unit price ($) | B23: =Bids!$D$5*(1+Bids!$D$9)^(B$21-1) -> 4650 | C23: =Bids!$D$5*(1+Bids!$D$9)^(C$21-1) -> 4743 | D23: =Bids!$D$5*(1+Bids!$D$9)^(D$21-1) -> 4837.86 | E23: =Bids!$D$5*(1+Bids!$D$9)^(E$21-1) -> 4934.6172 | F23: =Bids!$D$5*(1+Bids!$D$9)^(F$21-1) -> 5033.3095
A24: Purchase cost | B24: =B22*B23 -> 643846.15 | C24: =C22*C23 -> 656723.08 | D24: =D22*D23 -> 669857.54 | E24: =E22*E23 -> 683254.69 | F24: =F22*F23 -> 696919.78 | G24: =SUM(B24:F24) -> 3350601.2
A25: Freight | B25: =B22*Bids!$D$7 -> 16615.385 | C25: =C22*Bids!$D$7 -> 16615.385 | D25: =D22*Bids!$D$7 -> 16615.385 | E25: =E22*Bids!$D$7 -> 16615.385 | F25: =F22*Bids!$D$7 -> 16615.385 | G25: =SUM(B25:F25) -> 83076.923
A26: Onsite support fee | B26: =Bids!$D$8 -> 8000 | C26: =Bids!$D$8 -> 8000 | D26: =Bids!$D$8 -> 8000 | E26: =Bids!$D$8 -> 8000 | F26: =Bids!$D$8 -> 8000 | G26: =SUM(B26:F26) -> 40000
A27: Premature failures (tires) | B27: =B22*Bids!$D$10 -> 2.7692308 | C27: =C22*Bids!$D$10 -> 2.7692308 | D27: =D22*Bids!$D$10 -> 2.7692308 | E27: =E22*Bids!$D$10 -> 2.7692308 | F27: =F22*Bids!$D$10 -> 2.7692308 | G27: =SUM(B27:F27) -> 13.846154
A28: Downtime cost | B28: =B27*Assumptions!$B$8*Assumptions!$B$9 -> 7476.9231 | C28: =C27*Assumptions!$B$8*Assumptions!$B$9 -> 7476.9231 | D28: =D27*Assumptions!$B$8*Assumptions!$B$9 -> 7476.9231 | E28: =E27*Assumptions!$B$8*Assumptions!$B$9 -> 7476.9231 | F28: =F27*Assumptions!$B$8*Assumptions!$B$9 -> 7476.9231 | G28: =SUM(B28:F28) -> 37384.615
A29: Warranty credit | B29: =-B27*B23*Bids!$D$11 -> -9657.6923 | C29: =-C27*C23*Bids!$D$11 -> -9850.8462 | D29: =-D27*D23*Bids!$D$11 -> -10047.863 | E29: =-E27*E23*Bids!$D$11 -> -10248.82 | F29: =-F27*F23*Bids!$D$11 -> -10453.797 | G29: =SUM(B29:F29) -> -50259.019
A30: Working-capital benefit (payment terms) | B30: =-B24*Assumptions!$B$10*Bids!$D$12/365 -> -3704.3203 | C30: =-C24*Assumptions!$B$10*Bids!$D$12/365 -> -3778.4067 | D30: =-D24*Assumptions!$B$10*Bids!$D$12/365 -> -3853.9749 | E30: =-E24*Assumptions!$B$10*Bids!$D$12/365 -> -3931.0544 | F30: =-F24*Assumptions!$B$10*Bids!$D$12/365 -> -4009.6755 | G30: =SUM(B30:F30) -> -19277.432
A31: Total annual cost | B31: =B24+B25+B26+B28+B29+B30 -> 662576.45 | C31: =C24+C25+C26+C28+C29+C30 -> 675186.13 | D31: =D24+D25+D26+D28+D29+D30 -> 688048.01 | E31: =E24+E25+E26+E28+E29+E30 -> 701167.12 | F31: =F24+F25+F26+F28+F29+F30 -> 714548.62 | G31: =SUM(B31:F31) -> 3441526.3
A32: Discount factor | B32: =1/(1+Assumptions!$B$10)^B$21 -> 0.93457944 | C32: =1/(1+Assumptions!$B$10)^C$21 -> 0.87343873 | D32: =1/(1+Assumptions!$B$10)^D$21 -> 0.81629788 | E32: =1/(1+Assumptions!$B$10)^E$21 -> 0.76289521 | F32: =1/(1+Assumptions!$B$10)^F$21 -> 0.71298618
A33: Present value | B33: =B31*B32 -> 619230.33 | C33: =C31*C32 -> 589733.72 | D33: =D31*D32 -> 561652.13 | E33: =E31*E32 -> 534917.04 | F33: =F31*F32 -> 509463.29 | G33: =SUM(B33:F33) -> 2814996.5
A36: =Bids!E4 -> Prairie Rubber
A37: Cost line | B37: 1 | C37: 2 | D37: 3 | E37: 4 | F37: 5 | G37: 5-Year total
A38: Tires purchased (avg per year) | B38: =Assumptions!$B$7/Bids!$E$6 -> 189.47368 | C38: =Assumptions!$B$7/Bids!$E$6 -> 189.47368 | D38: =Assumptions!$B$7/Bids!$E$6 -> 189.47368 | E38: =Assumptions!$B$7/Bids!$E$6 -> 189.47368 | F38: =Assumptions!$B$7/Bids!$E$6 -> 189.47368 | G38: =SUM(B38:F38) -> 947.36842
A39: Unit price ($) | B39: =Bids!$E$5*(1+Bids!$E$9)^(B$37-1) -> 3700 | C39: =Bids!$E$5*(1+Bids!$E$9)^(C$37-1) -> 3866.5 | D39: =Bids!$E$5*(1+Bids!$E$9)^(D$37-1) -> 4040.4925 | E39: =Bids!$E$5*(1+Bids!$E$9)^(E$37-1) -> 4222.3147 | F39: =Bids!$E$5*(1+Bids!$E$9)^(F$37-1) -> 4412.3188
A40: Purchase cost | B40: =B38*B39 -> 701052.63 | C40: =C38*C39 -> 732600 | D40: =D38*D39 -> 765567 | E40: =E38*E39 -> 800017.51 | F40: =F38*F39 -> 836018.3 | G40: =SUM(B40:F40) -> 3835255.4
A41: Freight | B41: =B38*Bids!$E$7 -> 11368.421 | C41: =C38*Bids!$E$7 -> 11368.421 | D41: =D38*Bids!$E$7 -> 11368.421 | E41: =E38*Bids!$E$7 -> 11368.421 | F41: =F38*Bids!$E$7 -> 11368.421 | G41: =SUM(B41:F41) -> 56842.105
A42: Onsite support fee | B42: =Bids!$E$8 -> 0 | C42: =Bids!$E$8 -> 0 | D42: =Bids!$E$8 -> 0 | E42: =Bids!$E$8 -> 0 | F42: =Bids!$E$8 -> 0 | G42: =SUM(B42:F42) -> 0
A43: Premature failures (tires) | B43: =B38*Bids!$E$10 -> 15.157895 | C43: =C38*Bids!$E$10 -> 15.157895 | D43: =D38*Bids!$E$10 -> 15.157895 | E43: =E38*Bids!$E$10 -> 15.157895 | F43: =F38*Bids!$E$10 -> 15.157895 | G43: =SUM(B43:F43) -> 75.789474
A44: Downtime cost | B44: =B43*Assumptions!$B$8*Assumptions!$B$9 -> 40926.316 | C44: =C43*Assumptions!$B$8*Assumptions!$B$9 -> 40926.316 | D44: =D43*Assumptions!$B$8*Assumptions!$B$9 -> 40926.316 | E44: =E43*Assumptions!$B$8*Assumptions!$B$9 -> 40926.316 | F44: =F43*Assumptions!$B$8*Assumptions!$B$9 -> 40926.316 | G44: =SUM(B44:F44) -> 204631.58
A45: Warranty credit | B45: =-B43*B39*Bids!$E$11 -> -14021.053 | C45: =-C43*C39*Bids!$E$11 -> -14652 | D45: =-D43*D39*Bids!$E$11 -> -15311.34 | E45: =-E43*E39*Bids!$E$11 -> -16000.35 | F45: =-F43*F39*Bids!$E$11 -> -16720.366 | G45: =SUM(B45:F45) -> -76705.109
...

Sheet TCO_Summary
A1: TCO Summary: Lowest Price vs Lowest Cost
A2: SIMULATED EXERCISE: all suppliers, prices, and performance data are fictitious and created for portfolio demonstration only.
A4: Supplier | B4: Unit price ($) | C4: 5-year nominal TCO ($) | D4: 5-year NPV TCO ($) | E4: NPV vs lowest ($) | F4: NPV vs lowest (%) | G4: Rank by unit price (1 = lowest) | H4: Rank by NPV TCO (1 = lowest) | I4: TCO score (1 to 5)
A5: =Bids!C4 -> Northfield Tire | B5: =Bids!C5 -> 4200 | C5: =TCO!G15 -> 3679994.4 | D5: =TCO!G17 -> 3006408.3 | E5: =D5-MIN($D$5:$D$7) -> 191411.75 | F5: =D5/MIN($D$5:$D$7)-1 -> 0.067997154 | G5: =RANK(B5,$B$5:$B$7,1) -> 2 | H5: =RANK(D5,$D$5:$D$7,1) -> 2 | I5: =5*MIN($D$5:$D$7)/D5 -> 4.6816604
A6: =Bids!D4 -> Summit Tread | B6: =Bids!D5 -> 4650 | C6: =TCO!G31 -> 3441526.3 | D6: =TCO!G33 -> 2814996.5 | E6: =D6-MIN($D$5:$D$7) -> 0 | F6: =D6/MIN($D$5:$D$7)-1 -> 0 | G6: =RANK(B6,$B$5:$B$7,1) -> 3 | H6: =RANK(D6,$D$5:$D$7,1) -> 1 | I6: =5*MIN($D$5:$D$7)/D6 -> 5
A7: =Bids!E4 -> Prairie Rubber | B7: =Bids!E5 -> 3700 | C7: =TCO!G47 -> 3975892.3 | D7: =TCO!G49 -> 3242316.1 | E7: =D7-MIN($D$5:$D$7) -> 427319.55 | F7: =D7/MIN($D$5:$D$7)-1 -> 0.1518011 | G7: =RANK(B7,$B$5:$B$7,1) -> 1 | H7: =RANK(D7,$D$5:$D$7,1) -> 3 | I7: =5*MIN($D$5:$D$7)/D7 -> 4.3410273
A9: TCO score = 5 x (lowest NPV TCO / supplier NPV TCO). The lowest-cost supplier scores 5.00.

Sheet Scoring
A1: Weighted Scoring
A2: SIMULATED EXERCISE: all suppliers, prices, and performance data are fictitious and created for portfolio demonstration only.
A4: Criterion | B4: Weight | C4: =Bids!C4 -> Northfield Tire | D4: =Bids!D4 -> Summit Tread | E4: =Bids!E4 -> Prairie Rubber
A5: =Criteria!A5 -> Total cost of ownership | B5: =Criteria!B5 -> 0.4 | C5: =TCO_Summary!I5 -> 4.6816604 | D5: =TCO_Summary!I6 -> 5 | E5: =TCO_Summary!I7 -> 4.3410273
A6: =Criteria!A6 -> Technical performance & quality | B6: =Criteria!B6 -> 0.2 | C6: 4 | D6: 5 | E6: 3
A7: =Criteria!A7 -> Delivery & service | B7: =Criteria!B7 -> 0.15 | C7: 4 | D7: 3 | E7: 4
A8: =Criteria!A8 -> Supplier risk & compliance | B8: =Criteria!B8 -> 0.1 | C8: 4 | D8: 4 | E8: 3
A9: =Criteria!A9 -> Commercial terms | B9: =Criteria!B9 -> 0.1 | C9: 3 | D9: 4 | E9: 3
A10: =Criteria!A10 -> Sustainability & safety practices | B10: =Criteria!B10 -> 0.05 | C10: 3 | D10: 4 | E10: 2
A11: Weighted score (out of 5) | B11: =SUM(B5:B10) -> 1 | C11: =SUMPRODUCT($B$5:$B$10,C5:C10) -> 4.1226642 | D11: =SUMPRODUCT($B$5:$B$10,D5:D10) -> 4.45 | E11: =SUMPRODUCT($B$5:$B$10,E5:E10) -> 3.6364109
A12: Weighted score (% of maximum) | C12: =C11/5 -> 0.82453283 | D12: =D11/5 -> 0.89 | E12: =E11/5 -> 0.72728218
A13: Rank (1 = best) | C13: =RANK(C11,$C$11:$E$11) -> 2 | D13: =RANK(D11,$C$11:$E$11) -> 1 | E13: =RANK(E11,$C$11:$E$11) -> 3
A16: Scoring rationale (invented evaluator notes) | C16: Northfield Tire | D16: Summit Tread | E16: Prairie Rubber
A17: Technical performance & quality | C17: Mid-range life (4,500 h), 4% failure rate | D17: Longest life (5,200 h), lowest failure rate (2%) | E17: Shortest life (3,800 h), 8% failure rate
A18: Delivery & service | C18: 4-week lead time, 95% on time, paid support | D18: 6-week lead time, 92% on time; slowest delivery | E18: 3-week lead time, 96% on time; no onsite support
A19: Supplier risk & compliance | C19: Stable, complete insurance and safety documents | D19: Stable, complete documents, strong references | E19: Thin financials, incomplete safety records
A20: Commercial terms | C20: 45-day terms, 3% escalation, 50% warranty credit | D20: 30-day terms, 2% escalation cap, 75% warranty credit | E20: 60-day terms but 4.5% escalation, 25% warranty credit
A21: Sustainability & safety practices | C21: Retread program offered | D21: Retread and recycling program, strong safety record | E21: No recycling program offered

Sheet Sensitivity
A1: Sensitivity: How Robust Is the Award Decision?
A2: SIMULATED EXERCISE: all suppliers, prices, and performance data are fictitious and created for portfolio demonstration only.
A4: Weighting scenario | B4: TCO weight | C4: =Bids!C4 -> Northfield Tire | D4: =Bids!D4 -> Summit Tread | E4: =Bids!E4 -> Prairie Rubber | F4: Winner
A5: Base case | B5: =Criteria!B5 -> 0.4 | C5: =$B5*Scoring!C5+(1-$B5)/(1-Criteria!$B$5)*SUMPRODUCT(Criteria!$B$6:$B$10,Scoring!C6:C10) -> 4.1226642 | D5: =$B5*Scoring!D5+(1-$B5)/(1-Criteria!$B$5)*SUMPRODUCT(Criteria!$B$6:$B$10,Scoring!D6:D10) -> 4.45 | E5: =$B5*Scoring!E5+(1-$B5)/(1-Criteria!$B$5)*SUMPRODUCT(Criteria!$B$6:$B$10,Scoring!E6:E10) -> 3.6364109 | F5: =INDEX($C$4:$E$4,MATCH(MAX(C5:E5),C5:E5,0)) -> Summit Tread
A6: Cost-focused | B6: 0.6 | C6: =$B6*Scoring!C5+(1-$B6)/(1-Criteria!$B$5)*SUMPRODUCT(Criteria!$B$6:$B$10,Scoring!C6:C10) -> 4.3089962 | D6: =$B6*Scoring!D5+(1-$B6)/(1-Criteria!$B$5)*SUMPRODUCT(Criteria!$B$6:$B$10,Scoring!D6:D10) -> 4.6333333 | E6: =$B6*Scoring!E5+(1-$B6)/(1-Criteria!$B$5)*SUMPRODUCT(Criteria!$B$6:$B$10,Scoring!E6:E10) -> 3.871283 | F6: =INDEX($C$4:$E$4,MATCH(MAX(C6:E6),C6:E6,0)) -> Summit Tread
A7: Quality-focused | B7: 0.25 | C7: =$B7*Scoring!C5+(1-$B7)/(1-Criteria!$B$5)*SUMPRODUCT(Criteria!$B$6:$B$10,Scoring!C6:C10) -> 3.9829151 | D7: =$B7*Scoring!D5+(1-$B7)/(1-Criteria!$B$5)*SUMPRODUCT(Criteria!$B$6:$B$10,Scoring!D6:D10) -> 4.3125 | E7: =$B7*Scoring!E5+(1-$B7)/(1-Criteria!$B$5)*SUMPRODUCT(Criteria!$B$6:$B$10,Scoring!E6:E10) -> 3.4602568 | F7: =INDEX($C$4:$E$4,MATCH(MAX(C7:E7),C7:E7,0)) -> Summit Tread
A8: TCO ignored (non-cost only) | B8: 0 | C8: =$B8*Scoring!C5+(1-$B8)/(1-Criteria!$B$5)*SUMPRODUCT(Criteria!$B$6:$B$10,Scoring!C6:C10) -> 3.75 | D8: =$B8*Scoring!D5+(1-$B8)/(1-Criteria!$B$5)*SUMPRODUCT(Criteria!$B$6:$B$10,Scoring!D6:D10) -> 4.0833333 | E8: =$B8*Scoring!E5+(1-$B8)/(1-Criteria!$B$5)*SUMPRODUCT(Criteria!$B$6:$B$10,Scoring!E6:E10) -> 3.1666667 | F8: =INDEX($C$4:$E$4,MATCH(MAX(C8:E8),C8:E8,0)) -> Summit Tread
A10: Non-TCO criteria keep their relative weights and are rescaled so all weights sum to 100% in each scenario.

Sheet Recommendation
A1: Award Recommendation (simulated)
A2: SIMULATED EXERCISE: all suppliers, prices, and performance data are fictitious and created for portfolio demonstration only.
A4: Item | B4: Result
A5: Recommended supplier (highest weighted score) | B5: =INDEX(Scoring!C4:E4,MATCH(MAX(Scoring!C11:E11),Scoring!C11:E11,0)) -> Summit Tread
A6: Weighted score (out of 5) | B6: =MAX(Scoring!C11:E11) -> 4.45
A7: Recommended supplier 5-year NPV TCO | B7: =INDEX(TCO_Summary!D5:D7,MATCH(B5,TCO_Summary!A5:A7,0)) -> 2814996.5
A8: Lowest unit-price bidder | B8: =INDEX(TCO_Summary!A5:A7,MATCH(MIN(TCO_Summary!B5:B7),TCO_Summary!B5:B7,0)) -> Prairie Rubber
A9: Lowest unit-price bidder 5-year NPV TCO | B9: =INDEX(TCO_Summary!D5:D7,MATCH(B8,TCO_Summary!A5:A7,0)) -> 3242316.1
A10: Extra 5-year NPV cost of choosing the lowest unit price | B10: =B9-B7 -> 427319.55
A11: Same winner in every sensitivity scenario? | B11: =IF(COUNTIF(Sensitivity!F5:F8,B5)=4,"Yes","No: review Sensitivity sheet") -> Yes
A13: Narrative (written for the base case as built; revisit if inputs change)
A14: Finding | B14: The lowest unit price does not give the lowest cost. Prairie Rubber's cheaper tires wear out sooner and fail early more often, so downtime and replacement volume outweigh the saving. Summit Tread has the highest unit price but the lowest 5-year NPV cost.
A15: Trade-off | B15: Summit Tread has the slowest lead time (6 weeks) and the shortest payment terms (30 days). Negotiate a lead-time commitment with a stock-holding or consignment arrangement.
A16: Negotiation levers | B16: Ask Summit Tread for: 45-day payment terms; a written 2% escalation cap for all 5 years; a lead-time service level with a penalty; warranty credit paid within 30 days of a claim; and a freight rate at or below the competing bids ($60 to $85 per tire versus its $120), or a delivered-price commitment. Cutting freight from $120 to $85 per tire saves about $24K over 5 years before discounting (692 tires x $35).
A17: Risks | B17: Failure rates and tire life are supplier-reported. Mitigate with a 3-month site trial, warranty-claim reporting, and an option to re-source a share of volume if life falls below 90% of the guaranteed hours.
A18: Next steps | B18: Verify references, confirm insurance, finalize the agreement draft, and set renewal and expiry reminders in the contract repository.
